Workbook

Sheet DG_quarterly_balance-sheet
A1: name | B1: 45138 | C1: 45046 | D1: 44957 | E1: 44865 | F1: 44773 | G1: 44681 | H1: 44592 | I1: 44500 | J1: 44408 | K1: 44316 | L1: 44227 | M1: 44135 | N1: 44043 | O1: 43951 | P1: 43861 | Q1: 43769 | R1: 43677 | S1: 43585 | T1: 43496 | U1: 43404 | V1: 43312 | W1: 43220 | X1: 43131 | Y1: 43039 | Z1: 42947 | AA1: 42855 | AB1: 42766 | AC1: 42674 | AD1: 42582 | AE1: 42490 | AF1: 42400 | AG1: 42308 | AH1: 42216 | AI1: 42124 | AJ1: 42035 | AK1: 41943 | AL1: 41851 | AM1: 41759 | AN1: 41670 | AO1: 41578 | AP1: 41486 | AQ1: 41394 | AR1: 41305 | AS1: 41213 | AT1: 41121 | AU1: 41029 | AV1: 40939 | AW1: 40847 | AX1: 40755 | AY1: 40663 | AZ1: 40574 | BA1: 40482 | BB1: 40390 | BC1: 40298 | BD1: 40209 | BE1: 40117 | BF1: 40025 | BG1: 39933 | BH1: 39844 | BI1: 39752 | BJ1: 39660 | BK1: 39568 | BL1: 39478 | BM1: 39202 | BN1: 39113 | BO1: 39021 | BP1: 38929 | BQ1: 38837 | BR1: 38748 | BS1: 38656 | BT1: 38564 | BU1: 38472 | BV1: 38383 | BW1: 38291 | BX1: 38199 | BY1: 38107 | BZ1: 38017 | CA1: 37925 | CB1: 37833 | CC1: 37741 | CD1: 37652 | CE1: 37560 | CF1: 37468 | CG1: 37376 | CH1: 37287 | CI1: 37195 | CJ1: 37103 | CK1: 37011 | CL1: 36922 | CM1: 36830 | CN1: 36738 | CO1: 36646 | CP1: 36556 | CQ1: 36464 | CR1: 36372 | CS1: 36280 | CT1: 36191 | CU1: 36099 | CV1: 36007 | CW1: 35915 | CX1: 35826 | CY1: 35734 | CZ1: 35642 | DA1: 35550 | DB1: 35461 | DC1: 35369 | DD1: 35277 | DE1: 35185 | DF1: 35095 | DG1: 35003 | DH1: 34911 | DI1: 34819 | DJ1: 34730 | DK1: 34638 | DL1: 34546 | DM1: 34454 | DN1: 34365 | DO1: 34273 | DP1: 34181 | DQ1: 34089 | DR1: 34000 | DS1: 33908 | DT1: 33816 | DU1: 33724 | DV1: 33634 | DW1: 33542 | DX1: 33450 | DY1: 33358 | DZ1: 33269 | EA1: 33177 | EB1: 33085 | EC1: 32993 | ED1: 32904 | EE1: 32812 | EF1: 32720 | EG1: 32539 | EH1: 32142 | EI1: 31777 | EJ1: 31412
A2: TotalAssets | B2: 30395557000 | C2: 29803933000 | D2: 29083367000 | E2: 29007158000 | F2: 28239256000 | G2: 26956308000 | H2: 26327371000 | I2: 25925302000 | J2: 25487808000 | K2: 25236698000 | L2: 25862624000 | M2: 26153442000 | N2: 25847433000 | O2: 24848313000 | P2: 22825084000 | Q2: 22412790000 | R2: 21917529000 | S2: 21304284000 | T2: 13204038000 | U2: 13121021000 | V2: 12943949000 | W2: 12493230000 | X2: 12516911000 | Y2: 12374756000 | Z2: 12120824000 | AA2: 11796355000 | AB2: 11672298000 | AC2: 11917076000 | AD2: 11617370000 | AE2: 11316384000 | AF2: 11257885000 | AG2: 11288293000 | AH2: 11195195000 | AI2: 10956550000 | AJ2: 11224104000 | AK2: 10877372000 | AL2: 10825794000 | AM2: 10601884000 | AN2: 10867524000 | AO2: 10775974000 | AP2: 10699630000 | AQ2: 10493697000 | AR2: 10367682000 | AS2: 10273677000 | AT2: 10103474000 | AU2: 9770208000 | AV2: 9688520000 | AW2: 9735882000 | AX2: 9529103000 | AY2: 9714864000 | AZ2: 9546222000 | BA2: 9349574000 | BB2: 9179474000 | BC2: 8977076000 | BD2: 8863519000 | BE2: 9132532000 | BF2: 9139944000 | BG2: 8978801000 | BH2: 8889199000 | BI2: 8940101000 | BJ2: 8909790000 | BK2: 8662999000 | BL2: 8656431000 | BM2: 3074309000 | BN2: 3040514000 | BO2: 3206303000 | BP2: 3245197000 | BQ2: 3063467000 | BR2: 2992187000 | BS2: 2930781000 | BT2: 2840366000 | BU2: 2904538000 | BV2: 2841004000 | BW2: 2828017000 | BX2: 2655005000 | BY2: 2673769000 | BZ2: 2652709000 | CA2: 2589194000 | CB2: 2365381000 | CC2: 2355967000 | CD2: 2333153000 | CE2: 2411164000 | CF2: 2265229000 | CG2: 2588732000 | CH2: 2552385000 | CI2: 2469266000 | CJ2: 2330324000 | CK2: 2301594000 | CL2: 2282462000 | CM2: 1768009000 | CN2: 1626962000 | CO2: 1518270000 | CP2: 1450941000 | CQ2: 1549100000 | CR2: 1342100000 | CS2: 1325400000 | CT2: 1211784000 | CU2: 1299000000 | CV2: 1151200000 | CW2: 1016500000 | CX2: 914838000 | CY2: 1019600000 | CZ2: 864600000 | DA2: 796000000 | DB2: 718147000 | DC2: 845000000 | DD2: 719900000 | DE2: 732600000 | DF2: 679996000 | DG2: 769000000 | DH2: 647000000 | DI2: 622000000 | DJ2: 540868000 | DK2: 554900000 | DL2: 481000000 | DM2: 439800000 | DN2: 397200000 | DO2: 454400000 | DP2: 376200000 | DQ2: 374000000 | DR2: 316400000 | DS2: 357500000 | DT2: 297900000 | DU2: 292800000 | DV2: 237300000 | DW2: 297000000 | DX2: 260000000 | DY2: 244100000 | DZ2: 207700000 | EA2: 269900000 | EB2: 245500000 | EC2: 248800000 | ED2: 193800000 | EE2: 249900000 | EF2: 229900000 | EG2: 210300000 | EH2: 224900000 | EI2: 232400000 | EJ2: 227600000
A3: CurrentAssets | B3: 8413979000 | C3: 8055460000 | D3: 7581009000 | E3: 8017016000 | F3: 7682892000 | G3: 6736870000 | H3: 6303843000 | I3: 6181834000 | J3: 5992718000 | K3: 6041745000 | L3: 6914219000 | M3: 7533432000 | N3: 7597408000 | O3: 6992483000 | P3: 5177868000 | Q3: 5068542000 | R3: 4919138000 | S3: 4583769000 | T3: 4663020000 | U3: 4630344000 | V3: 4517826000 | W3: 4166036000 | X3: 4247852000 | Y3: 4153334000 | Z3: 3979991000 | AA3: 3748949000 | AB3: 3677771000 | AC3: 3968512000 | AD3: 3708051000 | AE3: 3477346000 | AF3: 3432410000 | AG3: 3488775000 | AH3: 3424847000 | AI3: 3244900000 | AJ3: 3532609000 | AK3: 3179132000 | AL3: 3140631000 | AM3: 2943346000 | AN3: 3205607000 | AO3: 2904302000 | AP3: 2864743000 | AQ3: 2724476000 | AR3: 2677113000 | AS3: 2618192000 | AT3: 2514444000 | AU3: 2273735000 | AV3: 2275074000 | AW3: 2392855000 | AX3: 2272781000 | AY3: 2506897000 | AZ3: 2367825000 | BA3: 2272758000 | BB3: 2134684000 | BC3: 1938578000 | BD3: 1845449000 | BE3: 2117314000 | BF3: 2145779000 | BG3: 1962148000 | BH3: 1870125000 | BI3: 1886297000 | BJ3: 1852801000 | BK3: 1595140000 | BL3: 1517744000 | BM3: 1786157000 | BN3: 1742748000 | BO3: 1917991000 | BP3: 1953880000 | BQ3: 1808755000 | BR3: 1762925000 | BS3: 1744650000 | BT3: 1698663000 | BU3: 1783195000 | BV3: 1730902000 | BW3: 1722234000 | BX3: 1586642000 | BY3: 1629658000 | BZ3: 1652215000 | CA3: 1598700000 | CB3: 1367308000 | CC3: 1355391000 | CD3: 1323908000 | CE3: 1390393000 | CF3: 1244105000 | CG3: 1588266000 | CH3: 1556047000 | CI3: 1346941000 | CJ3: 1140679000 | CK3: 1126236000 | CL3: 1124927000 | CM3: 1257107000 | CN3: 1164356000 | CO3: 1137045000 | CP3: 1095535000 | CQ3: 1213700000 | CR3: 1028800000 | CS3: 999100000 | CT3: 878917000 | CU3: 1003400000 | CV3: 874200000 | CW3: 756600000 | CX3: 666709000 | CY3: 775900000 | CZ3: 638400000 | DA3: 596800000 | DB3: 504599000 | DC3: 660500000 | DD3: 552200000 | DE3: 570500000 | DF3: 516243000 | DG3: 609500000 | DH3: 501600000 | DI3: 486900000 | DJ3: 410153000 | DK3: 442300000 | DL3: 383100000 | DM3: 353600000 | DN3: 315000000 | DO3: 377100000 | DP3: 305100000 | DQ3: 309700000 | DR3: 255700000 | DS3: 301300000 | DT3: 246600000 | DU3: 244900000 | DV3: 192400000 | DW3: 254400000 | DX3: 218900000 | DY3: 204100000 | DZ3: 168200000 | EA3: 229700000 | EB3: 206400000 | EC3: 210000000 | ED3: 155200000 | EE3: 212400000 | EF3: 196500000 | EG3: 182600000 | EH3: 190400000 | EI3: 194200000 | EJ3: 189400000
A4: CashCashEquivalentsAndShortTermInvestments | B4: 353018000 | C4: 313064000 | D4: 381576000 | E4: 362731000 | F4: 326263000 | G4: 335613000 | H4: 344829000 | I4: 488662000 | J4: 313666000 | K4: 688055000 | L4: 1376577000 | M4: 2199443000 | N4: 2959604000 | O4: 2673912000 | P4: 240320000 | Q4: 276076000 | R4: 259568000 | S4: 271111000 | T4: 235487000 | U4: 260688000 | V4: 265288000 | W4: 283970000 | X4: 267441000 | Y4: 226192000 | Z4: 214173000 | AA4: 205977000 | AB4: 187915000 | AC4: 200236000 | AD4: 185033000 | AE4: 187687000 | AF4: 157947000 | AG4: 182514000 | AH4: 180525000 | AI4: 225116000 | AJ4: 579823000 | AK4: 216155000 | AL4: 172474000 | AM4: 166330000 | AN4: 505566000 | AO4: 165717000 | AP4: 169220000 | AQ4: 155526000 | AR4: 140809000 | AS4: 142580000 | AT4: 134157000 | AU4: 132530000 | AV4: 126126000 | AW4: 118580000 | AX4: 113050000 | AY4: 602463000 | AZ4: 497446000 | BA4: 237906000 | BB4: 281421000 | BC4: 222709000 | BD4: 222076000 | BE4: 337019000 | BF4: 515375000 | BG4: 434584000 | BH4: 377995000 | BI4: 150590000 | BJ4: 264227000 | BK4: 164475000 | BL4: 119820000 | BM4: 231788000 | BN4: 219238000 | BO4: 120314000 | BP4: 107882000 | BQ4: 90701000 | BR4: 209459000 | BS4: 94186000 | BT4: 145950000 | BU4: 236523000 | BV4: 275755000 | BW4: 45832000 | BX4: 101465000 | BY4: 256883000 | BZ4: 398278000 | CA4: 138470000 | CB4: 102276000 | CC4: 75946000 | CD4: 121318000 | CE4: 37101000 | CF4: 39517000 | CG4: 287424000 | CH4: 261525000 | CI4: 74819000 | CJ4: 81630000 | CK4: 160894000 | CL4: 162310000 | CM4: 13080000 | CN4: 14040000 | CO4: 28397000 | CP4: 58789000 | CQ4: 35700000 | CR4: 25300000 | CS4: 25600000 | CT4: 22294000 | CU4: 18300000 | CV4: 33200000 | CW4: 37200000 | CX4: 7128000 | CY4: 13200000 | CZ4: 24900000 | DA4: 33400000 | DB4: 6563000 | DC4: 8800000 | DD4: 13000000 | DE4: 19400000 | DF4: 4344000 | DG4: 4100000 | DH4: 14000000 | DI4: 41100000 | DJ4: 33045000 | DK4: 25600000 | DL4: 26800000 | DM4: 30300000 | DN4: 35400000 | DO4: 33200000 | DP4: 22600000 | DQ4: 17400000 | DR4: 25000000 | DS4: 29300000 | DT4: 18100000 | DU4: 13900000 | DV4: 7900000 | DW4: 7600000 | DX4: 8800000 | DY4: 5900000 | DZ4: 3900000 | EA4: 12600000 | EB4: 7300000 | EC4: 8400000 | ED4: 6500000 | EE4: 2700000 | EF4: 3500000 | EG4: 5700000 | EH4: 7300000 | EI4: 5200000 | EJ4: 6800000
A5: CashAndCashEquivalents | B5: 353018000 | C5: 313064000 | D5: 381576000 | E5: 362731000 | F5: 326263000 | G5: 335613000 | H5: 344829000 | I5: 488662000 | J5: 313666000 | K5: 688055000 | L5: 1376577000 | M5: 2199443000 | N5: 2959604000 | O5: 2673912000 | P5: 240320000 | Q5: 276076000 | R5: 259568000 | S5: 271111000 | T5: 235487000 | U5: 260688000 | V5: 265288000 | W5: 283970000 | X5: 267441000 | Y5: 226192000 | Z5: 214173000 | AA5: 205977000 | AB5: 187915000 | AC5: 200236000 | AD5: 185033000 | AE5: 187687000 | AF5: 157947000 | AG5: 182514000 | AH5: 180525000 | AI5: 225116000 | AJ5: 579823000 | AK5: 216155000 | AL5: 172474000 | AM5: 166330000 | AN5: 505566000 | AO5: 165717000 | AP5: 169220000 | AQ5: 155526000 | AR5: 140809000 | AS5: 142580000 | AT5: 134157000 | AU5: 132530000 | AV5: 126126000 | AW5: 118580000 | AX5: 113050000 | AY5: 602463000 | AZ5: 497446000 | BA5: 237906000 | BB5: 281421000 | BC5: 222709000 | BD5: 222076000 | BE5: 337019000 | BF5: 515375000 | BG5: 434584000 | BH5: 377995000 | BI5: 150590000 | BJ5: 261630000 | BK5: 115904000 | BL5: 100209000 | BM5: 204417000 | BN5: 189288000 | BO5: 90914000 | BP5: 86352000 | BQ5: 71876000 | BR5: 200609000 | BS5: 92769000 | BT5: 145950000 | BU5: 236523000 | BV5: 232830000 | BW5: 45832000 | BX5: 101465000 | BY5: 256883000 | BZ5: 398278000 | CA5: 138470000 | CB5: 102276000 | CC5: 75946000 | CD5: 121318000 | CE5: 37101000 | CF5: 39517000 | CG5: 287424000 | CH5: 261525000 | CI5: 74819000 | CJ5: 81630000 | CK5: 160894000 | CL5: 162310000 | CM5: 13080000 | CN5: 14040000 | CO5: 28397000 | CP5: 58789000 | CQ5: 35700000 | CR5: 25300000 | CS5: 25600000 | CT5: 22294000 | CU5: 18300000 | CV5: 33200000 | CW5: 37200000 | CX5: 7128000 | CY5: 13200000 | CZ5: 24900000 | DA5: 33400000 | DB5: 6563000 | DC5: 8800000 | DD5: 13000000 | DE5: 19400000 | DF5: 4344000 | DG5: 4100000 | DH5: 14000000 | DI5: 41100000 | DJ5: 33045000 | DK5: 25600000 | DL5: 26800000 | DM5: 30300000 | DN5: 35400000 | DO5: 33200000 | DP5: 22600000 | DQ5: 17400000 | DR5: 25000000 | DS5: 29300000 | DT5: 18100000 | DU5: 13900000 | DV5: 7900000 | DW5: 7600000 | DX5: 8800000 | DY5: 5900000 | DZ5: 3900000 | EA5: 12600000 | EB5: 7300000 | EC5: 8400000 | ED5: 6500000 | EE5: 2700000 | EF5: 3500000 | EG5: 5700000 | EH5: 7300000 | EI5: 5200000 | EJ5: 6800000
A6: OtherShortTermInvestments | BH6: 0 | BI6: 0 | BJ6: 2597000 | BK6: 48571000 | BL6: 19611000 | BM6: 27371000 | BN6: 29950000 | BO6: 29400000 | BP6: 21530000 | BQ6: 18825000 | BR6: 8850000 | BS6: 1417000 | BT6: 0 | BU6: 0 | BV6: 42925000
A7: Receivables | B7: 151730000 | C7: 50863000 | D7: 135775000 | E7: 188082000 | F7: 93283000 | G7: 33576000 | H7: 97394000 | I7: 120374000 | J7: 127011000 | K7: 16637000 | L7: 90760000 | M7: 111139000 | N7: 36176000 | O7: 17191000 | P7: 76537000 | Q7: 103188000 | R7: 61692000 | S7: 25164000 | T7: 57804000 | U7: 114647000 | V7: 68353000 | W7: 28637000 | X7: 108265000 | Y7: 99678000 | Z7: 44255000 | AA7: 10492000 | AB7: 11050000 | AC7: 54586000 | AD7: 22985000 | AE7: 6827000 | AF7: 6843000 | AG7: 11877000 | AH7: 14646000 | AL7: 4237000 | AO7: 9786000 | AP7: 7894000 | AS7: 13554000 | AT7: 89473000 | AU7: 5210000 | AW7: 48807000 | AX7: 43435000 | AZ7: 0 | BA7: 27677000 | BB7: 0 | BC7: 0 | BD7: 7543000 | BE7: 31268000 | BF7: 5450000 | BG7: 3479000 | BH7: 6392000 | BI7: 42986000 | BJ7: 12829000 | BK7: 33813000 | BL7: 32501000 | BM7: 14624000 | BN7: 9833000 | BP7: 38753000 | CF7: 55573000 | EE7: 202400000
A8: TaxesReceivable | B8: 151730000 | C8: 50863000 | D8: 135775000 | E8: 188082000 | F8: 93283000 | G8: 33576000 | H8: 97394000 | I8: 120374000 | J8: 127011000 | K8: 16637000 | L8: 90760000 | M8: 111139000 | N8: 36176000 | O8: 17191000 | P8: 76537000 | Q8: 103188000 | R8: 61692000 | S8: 25164000 | T8: 57804000 | U8: 114647000 | V8: 68353000 | W8: 28637000 | X8: 108265000 | Y8: 99678000 | Z8: 44255000 | AA8: 10492000 | AB8: 11050000 | AC8: 54586000 | AD8: 22985000 | AE8: 6827000 | AF8: 6843000 | AG8: 11877000 | AH8: 14646000 | AL8: 4237000 | AO8: 9786000 | AP8: 7894000 | AS8: 13554000 | AT8: 89473000 | AU8: 5210000 | AW8: 48807000 | AX8: 43435000 | AZ8: 0 | BA8: 27677000 | BB8: 0 | BC8: 0 | BD8: 7543000 | BE8: 31268000 | BF8: 5450000 | BG8: 3479000 | BH8: 6392000 | BI8: 42986000 | BJ8: 12829000 | BK8: 33813000 | BL8: 32501000 | BM8: 14624000 | BN8: 9833000 | BP8: 38753000 | CF8: 55573000
A9: Inventory | B9: 7531459000 | C9: 7335845000 | D9: 6760733000 | E9: 7144722000 | F9: 6935856000 | G9: 6087399000 | H9: 5614325000 | I9: 5298859000 | J9: 5279273000 | K9: 5099465000 | L9: 5247477000 | M9: 5025810000 | N9: 4391157000 | O9: 4107331000 | P9: 4676848000 | Q9: 4496377000 | R9: 4419628000 | S9: 4109759000 | T9: 4097004000 | U9: 3979105000 | V9: 3896432000 | W9: 3594529000 | X9: 3609025000 | Y9: 3597195000 | Z9: 3463004000 | AA9: 3300082000 | AB9: 3258785000 | AC9: 3488247000 | AD9: 3270685000 | AE9: 3072063000 | AF9: 3074153000 | AG9: 3101908000 | AH9: 3029731000 | AI9: 2839198000 | AJ9: 2782521000 | AK9: 2788996000 | AL9: 2788872000 | AM9: 2605356000 | AN9: 2552993000 | AO9: 2591552000 | AP9: 2533766000 | AQ9: 2414411000 | AR9: 2397175000 | AS9: 2330436000 | AT9: 2147837000 | AU9: 2000864000 | AV9: 2009206000 | AW9: 2089722000 | AX9: 1973863000 | AY9: 1767121000 | AZ9: 1765433000 | BA9: 1885753000 | BB9: 1738439000 | BC9: 1604754000 | BD9: 1519578000 | BE9: 1680273000 | BF9: 1552586000 | BG9: 1454692000 | BH9: 1414955000 | BI9: 1619922000 | BJ9: 1490063000 | BK9: 1317097000 | BL9: 1288661000 | BM9: 1444313000 | BN9: 1432336000 | BO9: 1676057000 | BP9: 1735031000 | BQ9: 1636118000 | BR9: 1474414000 | BS9: 1574567000 | BT9: 1460700000 | BU9: 1465981000 | BV9: 1376537000 | BW9: 1558574000 | BX9: 1379543000 | BY9: 1277185000 | BZ9: 1157141000 | CA9: 1373200000 | CB9: 1184709000 | CC9: 1200701000 | CD9: 1123031000 | CE9: 1249120000 | CF9: 1058200000 | CG9: 1134449000 | CH9: 1131023000 | CI9: 1133215000 | CJ9: 980856000 | CK9: 905534000 | CL9: 896235000 | CM9: 1173328000 | CN9: 1062175000 | CO9: 995495000 | CP9: 985715000 | CQ9: 1105500000 | CR9: 951100000 | CS9: 939200000 | CT9: 811722000 | CU9: 944300000 | CV9: 797300000 | CW9: 692700000 | CX9: 631954000 | CY9: 737300000 | CZ9: 589700000 | DA9: 541000000 | DB9: 476103000 | DC9: 623400000 | DD9: 513700000 | DE9: 526100000 | DF9: 488362000 | DG9: 580900000 | DH9: 462600000 | DI9: 420000000 | DJ9: 356111000 | DK9: 392600000 | DL9: 332600000 | DM9: 304200000 | DN9: 260000000 | DO9: 322600000 | DP9: 263700000 | DQ9: 276900000 | DR9: 216800000 | DS9: 258100000 | DT9: 215200000 | DU9: 217400000 | DV9: 172800000 | DW9: 235200000 | DX9: 197600000 | DY9: 187600000 | DZ9: 154800000 | EA9: 208500000 | EB9: 191000000 | EC9: 192400000 | ED9: 140400000 | EF9: 186000000 | EG9: 171000000 | EH9: 177100000 | EI9: 183900000 | EJ9: 178200000
A10: FinishedGoods | B10: 7531459000 | C10: 7335845000 | D10: 6760733000 | E10: 7144722000 | F10: 6935856000 | G10: 6087399000 | H10: 5614325000 | I10: 5298859000 | J10: 5279273000 | K10: 5099465000 | L10: 5247477000 | M10: 5025810000 | N10: 4391157000 | O10: 4107331000 | P10: 4676848000 | Q10: 4496377000 | R10: 4419628000 | S10: 4109759000 | T10: 4097004000 | U10: 3979105000 | V10: 3896432000 | W10: 3594529000 | X10: 3609025000 | Y10: 3597195000 | Z10: 3463004000 | AA10: 3300082000 | AB10: 3258785000 | AC10: 3488247000 | AD10: 3270685000 | AE10: 3072063000 | AF10: 3074153000 | AG10: 3101908000 | AH10: 3029731000 | AI10: 2839198000 | AJ10: 2782521000 | AK10: 2788996000 | AL10: 2788872000 | AM10: 2605356000 | AN10: 2552993000 | AO10: 2591552000 | AP10: 2533766000 | AQ10: 2414411000 | AR10: 2397175000
A11: PrepaidAssets | E11: 321481000 | F11: 327490000 | G11: 280282000 | H11: 247295000 | I11: 273939000 | J11: 272768000 | K11: 237588000 | L11: 199405000 | M11: 197040000 | N11: 210471000 | O11: 194049000 | P11: 184163000 | Q11: 192901000 | R11: 178250000 | S11: 177735000 | T11: 272725000 | U11: 275904000 | V11: 287753000 | W11: 258900000 | X11: 263121000 | Y11: 230269000 | Z11: 258559000 | AA11: 232398000 | AB11: 220021000 | AC11: 225443000 | AD11: 229348000 | AE11: 210769000 | AF11: 193467000 | AG11: 192476000 | AH11: 199945000 | AI11: 180586000 | AJ11: 170265000 | AK11: 173981000 | AL11: 175048000 | AM11: 171660000 | AN11: 147048000 | AO11: 137247000 | AP11: 153863000 | AQ11: 154539000 | AR11: 139129000 | AS11: 131622000 | AT11: 142977000 | AU11: 135131000 | AV11: 139742000 | AW11: 135746000 | AX11: 142433000 | AY11: 137313000 | AZ11: 104946000 | BA11: 121422000 | BB11: 114824000 | BC11: 111115000 | BD11: 96252000 | BE11: 68754000 | BF11: 72368000 | BG11: 69393000 | BH11: 66183000 | BI11: 72799000 | BJ11: 68287000 | BK11: 64508000 | BL11: 59465000 | BM11: 57572000 | BN11: 57020000 | BO11: 71993000 | BP11: 71212000 | BQ11: 79569000 | BR11: 67140000 | BS11: 61549000 | BT11: 58305000 | BU11: 59166000 | BV11: 53702000
A12: CurrentDeferredAssets | BD12: 0 | BE12: 0 | BF12: 0 | BG12: 0 | BH12: 4600000 | BI12: 0 | BJ12: 17395000 | BK12: 15247000 | BL12: 17297000 | BM12: 37860000 | BN12: 24321000 | BO12: 49627000 | BP12: 1002000 | BQ12: 2367000 | BR12: 11912000 | BS12: 14348000 | BT12: 33708000 | BU12: 21525000 | BV12: 24908000 | BW12: 17305000 | BX12: 10997000 | BY12: 21852000 | BZ12: 30413000 | CA12: 21729000 | CB12: 22829000 | CC12: 26664000 | CD12: 33860000 | CE12: 43095000 | CF12: 25552000 | CG12: 80974000 | CH12: 105091000 | CI12: 90307000 | CJ12: 24962000 | CK12: 21912000 | CL12: 21514000 | CM12: 7743000 | CN12: 6936000 | CO12: 6682000 | CP12: 5995000 | CT12: 2523000 | CX12: 5743000 | DB12: 3689000 | DF12: 11989000 | DJ12: 11785000
A13: CurrentDeferredTaxesAssets | BD13: 0 | BE13: 0 | BF13: 0 | BG13: 0 | BH13: 4600000 | BI13: 0 | BJ13: 17395000 | BK13: 15247000 | BL13: 17297000 | BM13: 37860000 | BN13: 24321000 | BO13: 49627000 | BP13: 1002000 | BQ13: 2367000 | BR13: 11912000 | BS13: 14348000 | BT13: 33708000 | BU13: 21525000 | BV13: 24908000 | BW13: 17305000 | BX13: 10997000 | BY13: 21852000 | BZ13: 30413000 | CA13: 21729000 | CB13: 22829000 | CC13: 26664000 | CD13: 33860000 | CE13: 43095000 | CF13: 25552000 | CG13: 80974000 | CH13: 105091000 | CI13: 90307000 | CJ13: 24962000 | CK13: 21912000 | CL13: 21514000 | CM13: 7743000 | CN13: 6936000 | CO13: 6682000 | CP13: 5995000 | CT13: 2523000 | CX13: 5743000 | DB13: 3689000 | DF13: 11989000 | DJ13: 11785000
A14: OtherCurrentAssets | B14: 377772000 | C14: 355688000 | D14: 302925000 | E14: 321481000 | F14: 327490000 | G14: 280282000 | H14: 247295000 | I14: 273939000 | J14: 272768000 | K14: 237588000 | L14: 199405000 | M14: 197040000 | N14: 210471000 | O14: 194049000 | P14: 184163000 | Q14: 192901000 | R14: 178250000 | S14: 177735000 | T14: 272725000 | U14: 275904000 | V14: 287753000 | W14: 258900000 | X14: 263121000 | Y14: 230269000 | Z14: 258559000 | AA14: 232398000 | AB14: 220021000 | AC14: 225443000 | AD14: 229348000 | AE14: 210769000 | AF14: 193467000 | AG14: 192476000 | AH14: 199945000 | AI14: 180586000 | AJ14: 170265000 | AK14: 173981000 | AL14: 175048000 | AM14: 171660000 | AN14: 147048000 | AO14: 137247000 | AP14: 153863000 | AQ14: 154539000 | AR14: 139129000 | BW14: 100523000 | BX14: 94637000 | BY14: 73738000 | BZ14: 66383000 | CA14: 65301000 | CB14: 57494000 | CC14: 52080000 | CD14: 45699000 | CE14: 61077000 | CF14: 65263000 | CG14: 85419000 | CH14: 58408000 | CI14: 48600000 | CJ14: 53231000 | CK14: 37896000 | CL14: 44868000 | CM14: 62956000 | CN14: 81205000 | CO14: 106471000 | CP14: 45036000 | CQ14: 72500000 | CR14: 52400000 | CS14: 34300000 | CT14: 42378000 | CU14: 40800000 | CV14: 43700000 | CW14: 26700000 | CX14: 21884000 | CY14: 25400000 | CZ14: 23800000 | DA14: 22400000 | DB14: 18244000 | DC14: 28300000 | DD14: 25500000 | DE14: 25000000 | DF14: 11548000 | DG14: 24500000 | DH14: 25000000 | DI14: 25800000 | DJ14: 9212000 | DK14: 24100000 | DL14: 23700000 | DM14: 19100000 | DN14: 19600000 | DO14: 21300000 | DP14: 18800000 | DQ14: 15400000 | DR14: 13900000 | DS14: 13900000 | DT14: 13300000 | DU14: 13600000 | DV14: 11700000 | DW14: 11600000 | DX14: 12500000 | DY14: 10600000 | DZ14: 9500000 | EA14: 8600000 | EB14: 8100000 | EC14: 9200000 | ED14: 8300000 | EE14: 7300000 | EF14: 7000000 | EG14: 5900000 | EH14: 6000000 | EI14: 5100000 | EJ14: 4400000
A15: TotalNonCurrentAssets | B15: 21981578000 | C15: 21748473000 | D15: 21502358000 | E15: 20990142000 | F15: 20556364000 | G15: 20219438000 | H15: 20023528000 | I15: 19743468000 | J15: 19495090000 | K15: 19194953000 | L15: 18948405000 | M15: 18620010000 | N15: 18250025000 | O15: 17855830000 | P15: 17647216000 | Q15: 17344248000 | R15: 16998391000 | S15: 16720515000 | T15: 8541018000 | U15: 8490677000 | V15: 8426123000 | W15: 8327194000 | X15: 8269059000 | Y15: 8221422000 | Z15: 8140833000 | AA15: 8047406000 | AB15: 7994527000 | AC15: 7948564000 | AD15: 7909319000 | AE15: 7839038000 | AF15: 7825475000 | AG15: 7799518000 | AH15: 7770348000 | AI15: 7711650000 | AJ15: 7691495000 | AK15: 7698240000 | AL15: 7685163000 | AM15: 7658538000 | AN15: 7661917000 | AO15: 7871672000 | AP15: 7834887000 | AQ15: 7769221000 | AR15: 7690569000 | AS15: 7655485000 | AT15: 7589030000 | AU15: 7496473000 | AV15: 7413446000 | AW15: 7343027000 | AX15: 7256322000 | AY15: 7207967000 | AZ15: 7178397000 | BA15: 7076816000 | BB15: 7044790000 | BC15: 7038498000 | BD15: 7018070000 | BE15: 7015218000 | BF15: 6994165000 | BG15: 7016653000 | BH15: 7019074000 | BI15: 7053804000 | BJ15: 7056989000 | BK15: 7067859000 | BL15: 7138687000 | BM15: 1288152000 | BN15: 1297766000 | BO15: 1288312000 | BP15: 1291317000 | BQ15: 1254712000 | BR15: 1229262000 | BS15: 1186131000 | BT15: 1141703000 | BU15: 1121343000 | BV15: 1110102000 | BW15: 1105783000 | BX15: 1068363000 | BY15: 1044111000 | BZ15: 1000494000 | CA15: 990494000 | CB15: 998073000 | CC15: 1000576000 | CD15: 1009245000 | CE15: 1020771000 | CF15: 1021124000 | CG15: 1000466000 | CH15: 996338000 | CI15: 1122325000 | CJ15: 1189645000 | CK15: 1175358000 | CL15: 1157535000 | CM15: 510902000 | CN15: 462606000 | CO15: 381225000 | CP15: 355406000 | CQ15: 335400000 | CR15: 313300000 | CS15: 326300000 | CT15: 332867000 | CU15: 295600000 | CV15: 277000000 | CW15: 259900000 | CX15: 248129000 | CY15: 243700000 | CZ15: 226200000 | DA15: 199200000 | DB15: 213548000 | DC15: 184500000 | DD15: 167700000 | DE15: 162100000 | DF15: 163753000 | DG15: 159500000 | DH15: 145400000 | DI15: 135100000 | DJ15: 130715000 | DK15: 112600000 | DL15: 97900000 | DM15: 86200000 | DN15: 82200000 | DO15: 77300000 | DP15: 71100000 | DQ15: 64300000 | DR15: 60700000 | DS15: 56200000 | DT15: 51300000 | DU15: 47900000 | DV15: 44900000 | DW15: 42600000 | DX15: 41100000 | DY15: 40000000 | DZ15: 39500000 | EA15: 40200000 | EB15: 39100000 | EC15: 38800000 | ED15: 38600000 | EE15: 37500000 | EF15: 33400000 | EG15: 27700000 | EH15: 34500000 | EI15: 38200000 | EJ15: 38200000
A16: NetPPE | B16: 16379301000 | C16: 16146657000 | D16: 15906323000 | E16: 15396824000 | F16: 14967412000 | G16: 14634180000 | H16: 14439057000 | I16: 14160537000 | J16: 13909274000 | K16: 13614144000 | L16: 13373327000 | M16: 13045157000 | N16: 12675787000 | O16: 12280946000 | P16: 12074542000 | Q16: 11770451000 | R16: 11425752000 | S16: 11148751000 | T16: 2970806000 | U16: 2921943000 | V16: 2857274000 | W16: 2758369000 | X16: 2701282000 | Y16: 2654936000 | Z16: 2574816000 | AA16: 2487292000 | AB16: 2434456000 | AC16: 2388463000 | AD16: 2349119000 | AE16: 2278081000 | AF16: 2264062000 | AG16: 2237068000 | AH16: 2195857000 | AI16: 2135436000 | AJ16: 2116075000 | AK16: 2120572000 | AL16: 2106963000 | AM16: 2079832000 | AN16: 2080305000 | AO16: 2287410000 | AP16: 2244651000 | AQ16: 2177264000 | AR16: 2088665000 | AS16: 2047434000 | AT16: 1972205000 | AU16: 1878172000 | AV16: 1794960000 | AW16: 1716797000 | AX16: 1622991000 | AY16: 1562596000 | AZ16: 1524575000 | BA16: 1414700000 | BB16: 1377630000 | BC16: 1360868000 | BD16: 1328386000 | BE16: 1305858000 | BF16: 1273452000 | BG16: 1280835000 | BH16: 1268960000 | BI16: 1288848000 | BJ16: 1266722000 | BK16: 1250570000 | BL16: 1274245000 | BM16: 1212198000 | BN16: 1236874000 | BO16: 1246890000 | BP16: 1241219000 | BQ16: 1212386000 | BR16: 1192172000 | BS16: 1155281000 | BT16: 1121697000 | BU16: 1091997000 | BV16: 1080838000 | BW16: 1076627000 | BX16: 1039046000 | BY16: 1017647000 | BZ16: 989224000 | CA16: 979487000 | CB16: 986463000 | CC16: 988111000 | CD16: 993822000 | CE16: 1000265000 | CF16: 999273000 | CG16: 991477000 | CH16: 988915000 | CI16: 997790000 | CJ16: 1003224000 | CK16: 991039000 | CL16: 973094000 | CM16: 494943000 | CN16: 449670000 | CO16: 372200000 | CP16: 346473000 | CQ16: 324900000 | CR16: 303600000 | CS16: 316600000 | CT16: 326408000 | CU16: 289000000 | CV16: 270500000 | CW16: 253300000 | CX16: 241445000 | CY16: 238100000 | CZ16: 220900000 | DA16: 193800000 | DB16: 208536000 | DC16: 179400000 | DD16: 162600000 | DE16: 157000000 | DF16: 158587000 | DG16: 154000000 | DH16: 139700000 | DI16: 129600000 | DJ16: 125252000 | DK16: 107800000 | DL16: 93200000 | DM16: 81600000 | DN16: 77500000 | DO16: 71900000 | DP16: 66400000 | DQ16: 58500000 | DR16: 56100000 | DS16: 51700000 | DT16: 46800000 | DU16: 43400000 | DV16: 40400000 | DW16: 38000000 | DX16: 36300000 | DY16: 35200000 | DZ16: 34700000 | EA16: 34600000 | EB16: 33500000 | EC16: 33200000 | ED16: 32900000 | EE16: 32400000 | EF16: 28200000 | EG16: 22600000 | EH16: 25400000 | EI16: 29100000 | EJ16: 23500000
A17: GrossPPE | B17: 16379301000 | C17: 16146657000 | D17: 15906323000 | E17: 15396824000 | F17: 14967412000 | G17: 14634180000 | H17: 14439057000 | I17: 14160537000 | J17: 13909274000 | K17: 13614144000 | L17: 13373327000 | M17: 13045157000 | N17: 12675787000 | O17: 12280946000 | P17: 12074542000 | Q17: 11770451000 | R17: 11425752000 | S17: 11148751000 | T17: 5518977000 | X17: 5175292000 | AB17: 4595002000 | AF17: 4170486000 | AJ17: 3753557000 | AN17: 3452916000 | AR17: 3226898000 | AV17: 2680985000 | AZ17: 2177269000 | BD17: 1792373000 | BH17: 1561008000 | BW17: 1905578000 | BX17: 1833447000 | BY17: 1775496000 | CA17: 1667438000 | CB17: 1639164000 | CC17: 1606447000 | CE17: 1581427000 | CF17: 1547346000 | CG17: 1507414000 | CH17: 1473693000 | CI17: 1454268000 | CJ17: 1429373000 | CK17: 1386885000 | CL17: 1339554000 | CM17: 801837000 | CN17: 736444000 | CO17: 641158000 | CP17: 597537000 | CQ17: 560300000 | CR17: 523600000 | CS17: 533000000 | CT17: 528238000 | CU17: 477200000 | CV17: 445400000 | CW17: 416000000 | CX17: 391911000 | CY17: 378500000 | CZ17: 351800000 | DA17: 315700000 | DB17: 321917000 | DC17: 285100000 | DD17: 260700000 | DE17: 247800000 | DF17: 242628000 | DG17: 231500000 | DH17: 212300000 | DI17: 196700000 | DJ17: 187360000 | DK17: 165300000 | DL17: 147800000 | DM17: 132500000 | DN17: 124800000 | DO17: 116000000 | DP17: 108300000 | DQ17: 98300000 | DR17: 93500000 | DS17: 92400000 | DT17: 86300000 | DU17: 81000000 | DV17: 76600000 | DW17: 74100000 | DX17: 72800000 | DY17: 70100000 | DZ17: 68100000 | EA17: 69900000 | EB17: 67200000 | EC17: 65300000 | ED17: 63500000 | EE17: 65800000 | EF17: 60100000 | EG17: 52000000 | EH17: 49900000 | EI17: 49400000 | EJ17: 38600000
A18: Properties | D18: 0 | H18: 0 | L18: 0 | P18: 0 | T18: 0 | X18: 0 | AB18: 0 | AF18: 0 | AJ18: 0 | AN18: 0 | AR18: 0 | AV18: 0 | AZ18: 0 | BD18: 0 | BH18: 0 | CH18: 0 | CL18: 0
A19: LandAndImprovements | D19: 329381000 | H19: 323487000 | L19: 317797000 | P19: 306864000 | T19: 299725000 | X19: 291630000 | AB19: 273380000 | AF19: 255487000 | AJ19: 227704000 | AN19: 212014000 | AR19: 257695000 | AV19: 204562000 | AZ19: 174439000 | BD19: 137903000 | BH19: 137779000 | CH19: 144490000 | CL19: 119410000
A20: BuildingsAndImprovements | D20: 1561440000 | H20: 1446126000 | L20: 1329309000 | P20: 1290673000 | T20: 1219852000 | X20: 1116872000 | AB20: 1013227000 | AF20: 834884000 | AJ20: 800346000 | AN20: 765555000 | AR20: 773835000 | AV20: 622849000 | AZ20: 575305000 | BD20: 520867000 | BH20: 518933000 | CH20: 331795000 | CL20: 286476000
A21: MachineryFurnitureEquipment | D21: 5714456000 | H21: 4984534000 | L21: 4487665000 | P21: 3782016000 | T21: 3298594000 | X21: 3186406000 | AB21: 2797144000 | AF21: 2526843000 | AJ21: 2295590000 | AN21: 2078893000 | AR21: 1828573000 | AV21: 1500268000 | AZ21: 1235756000 | BD21: 992423000 | BH21: 781425000 | CH21: 988074000 | CL21: 823234000
A22: OtherProperties | B22: 16379301000 | C22: 16146657000 | D22: 15906323000 | E22: 15396824000 | F22: 14967412000 | G22: 14634180000 | H22: 14439057000 | I22: 14160537000 | J22: 13909274000 | K22: 13614144000 | L22: 13373327000 | M22: 13045157000 | N22: 12675787000 | O22: 12280946000 | P22: 12074542000 | Q22: 11770451000 | R22: 11425752000 | S22: 11148751000
A23: ConstructionInProgress | D23: 313615000 | H23: 131073000 | L23: 183593000 | P23: 62183000 | T23: 117275000 | X23: 72490000 | AB23: 72540000 | AF23: 150275000 | AJ23: 68360000 | AN23: 70332000 | AR23: 87444000 | AV23: 139454000 | AZ23: 17933000 | BD23: 10406000 | BH23: 5025000 | CH23: 9334000 | CL23: 110434000
A24: Leases | D24: 1011788000 | H24: 889782000 | L24: 782858000 | P24: 656234000 | T24: 583531000 | X24: 507894000 | AB24: 438711000 | AF24: 402997000 | AJ24: 361557000 | AN24: 326122000 | AR24: 279351000 | AV24: 213852000 | AZ24: 173836000 | BD24: 130774000 | BH24: 117846000
A25: AccumulatedDepreciation | D25: -3909423000 | H25: -3591647000 | L25: -3364333000 | P25: -2819611000 | T25: -2548171000 | X25: -2474010000 | AB25: -2160546000 | AF25: -1906424000 | AJ25: -1637482000 | AN25: -1372611000 | AR25: -1138233000 | AV25: -886025000 | AZ25: -652694000 | BD25: -463987000 | BH25: -292048000 | BW25: -828951000 | BX25: -794401000 | BY25: -757849000 | CA25: -687951000 | CB25: -652701000 | CC25: -618336000 | CE25: -581162000 | CF25: -548073000 | CG25: -515937000 | CH25: -484778000 | CI25: -456478000 | CJ25: -426149000 | CK25: -395846000 | CL25: -366460000 | CM25: -306894000 | CN25: -286774000 | CO25: -268958000 | CP25: -251064000 | CQ25: -235400000 | CR25: -220000000 | CS25: -216400000 | CT25: -201830000 | CU25: -188200000 | CV25: -174900000 | CW25: -162700000 | CX25: -150466000 | CY25: -140400000 | CZ25: -130900000 | DA25: -121900000 | DB25: -113381000 | DC25: -105700000 | DD25: -98100000 | DE25: -90800000 | DF25: -84041000 | DG25: -77500000 | DH25: -72600000 | DI25: -67100000 | DJ25: -62108000 | DK25: -57500000 | DL25: -54600000 | DM25: -50900000 | DN25: -47300000 | DO25: -44100000 | DP25: -41900000 | DQ25: -39800000 | DR25: -37400000 | DS25: -40700000 | DT25: -39500000 | DU25: -37600000 | DV25: -36200000 | DW25: -36100000 | DX25: -36500000 | DY25: -34900000 | DZ25: -33400000 | EA25: -35300000 | EB25: -33700000 | EC25: -32100000 | ED25: -30600000 | EE25: -33400000 | EF25: -31900000 | EG25: -29400000 | EH25: -24500000 | EI25: -20300000 | EJ25: -15100000
A26: GoodwillAndOtherIntangibleAssets | B26: 5538289000 | C26: 5538289000 | D26: 5538289000 | E26: 5538289000 | F26: 5538289000 | G26: 5538309000 | H26: 5538339000 | I26: 5538369000 | J26: 5538399000 | K26: 5538429000 | L26: 5538459000 | M26: 5538489000 | N26: 5538520000 | O26: 5538550000 | P26: 5538595000 | Q26: 5538648000 | R26: 5538700000 | S26: 5538753000 | T26: 5538806000 | U26: 5538859000 | V26: 5538911000 | W26: 5538964000 | X26: 5539017000 | Y26: 5539070000 | Z26: 5539126000 | AA26: 5539186000 | AB26: 5539248000 | AC26: 5539323000 | AD26: 5539405000 | AE26: 5539493000 | AF26: 5539583000 | AG26: 5539699000 | AH26: 5539830000 | AI26: 5540017000 | AJ26: 5540459000 | AK26: 5541240000 | AL26: 5542493000 | AM26: 5544187000 | AN26: 5546234000 | AO26: 5548666000 | AP26: 5551410000 | AQ26: 5554588000 | AR26: 5558132000 | AS26: 5561996000 | AT26: 5566088000 | AU26: 5570455000 | AV26: 5574543000 | AW26: 5579322000 | AX26: 5584362000 | AY26: 5589878000 | AZ26: 5595511000 | BA26: 5601423000 | BB26: 5607579000 | BC26: 5614762000 | BD26: 5622872000 | BE26: 5631869000 | BF26: 5641785000 | BG26: 5653014000 | BH26: 5664147000 | BI26: 5673926000 | BJ26: 5692878000 | BK26: 5704020000 | BL26: 5715487000
A27: Goodwill | B27: 4338589000 | C27: 4338589000 | D27: 4338589000 | E27: 4338589000 | F27: 4338589000 | G27: 4338589000 | H27: 4338589000 | I27: 4338589000 | J27: 4338589000 | K27: 4338589000 | L27: 4338589000 | M27: 4338589000 | N27: 4338589000 | O27: 4338589000 | P27: 4338589000 | Q27: 4338589000 | R27: 4338589000 | S27: 4338589000 | T27: 4338589000 | U27: 4338589000 | V27: 4338589000 | W27: 4338589000 | X27: 4338589000 | Y27: 4338589000 | Z27: 4338589000 | AA27: 4338589000 | AB27: 4338589000 | AC27: 4338589000 | AD27: 4338589000 | AE27: 4338589000 | AF27: 4338589000 | AG27: 4338589000 | AH27: 4338589000 | AI27: 4338589000 | AJ27: 4338589000 | AK27: 4338589000 | AL27: 4338589000 | AM27: 4338589000 | AN27: 4338589000 | AO27: 4338589000 | AP27: 4338589000 | AQ27: 4338589000 | AR27: 4338589000 | AS27: 4338589000 | AT27: 4338589000 | AU27: 4338589000 | AV27: 4338589000 | AW27: 4338589000 | AX27: 4338589000 | AY27: 4338589000 | AZ27: 4338589000 | BA27: 4338589000 | BB27: 4338589000 | BC27: 4338589000 | BD27: 4338589000 | BE27: 4338589000 | BF27: 4338589000 | BG27: 4338589000 | BH27: 4338589000 | BI27: 4337152000 | BJ27: 4344930000 | BK27: 4344930000 | BL27: 4344930000
A28: OtherIntangibleAssets | B28: 1199700000 | C28: 1199700000 | D28: 1199700000 | E28: 1199700000 | F28: 1199700000 | G28: 1199720000 | H28: 1199750000 | I28: 1199780000 | J28: 1199810000 | K28: 1199840000 | L28: 1199870000 | M28: 1199900000 | N28: 1199931000 | O28: 1199961000 | P28: 1200006000 | Q28: 1200059000 | R28: 1200111000 | S28: 1200164000 | T28: 1200217000 | U28: 1200270000 | V28: 1200322000 | W28: 1200375000 | X28: 1200428000 | Y28: 1200481000 | Z28: 1200537000 | AA28: 1200597000 | AB28: 1200659000 | AC28: 1200734000 | AD28: 1200816000 | AE28: 1200904000 | AF28: 1200994000 | AG28: 1201110000 | AH28: 1201241000 | AI28: 1201428000 | AJ28: 1201870000 | AK28: 1202651000 | AL28: 1203904000 | AM28: 1205598000 | AN28: 1207645000 | AO28: 1210077000 | AP28: 1212821000 | AQ28: 1215999000 | AR28: 1219543000 | AS28: 1223407000 | AT28: 1227499000 | AU28: 1231866000 | AV28: 1235954000 | AW28: 1240733000 | AX28: 1245773000 | AY28: 1251289000 | AZ28: 1256922000 | BA28: 1262834000 | BB28: 1268990000 | BC28: 1276173000 | BD28: 1284283000 | BE28: 1293280000 | BF28: 1303196000 | BG28: 1314425000 | BH28: 1325558000 | BI28: 1336774000 | BJ28: 1347948000 | BK28: 1359090000 | BL28: 1370557000
A29: NonCurrentDeferredAssets | BM29: 12418000 | CH29: 0 | CL29: 52708000
A30: NonCurrentDeferredTaxesAssets | BM30: 12418000 | CH30: 0 | CL30: 52708000
A31: OtherNonCurrentAssets | B31: 63988000 | C31: 63527000 | D31: 57746000 | E31: 55029000 | F31: 50663000 | G31: 46949000 | H31: 46132000 | I31: 44562000 | J31: 47417000 | K31: 42380000 | L31: 36619000 | M31: 36364000 | N31: 35718000 | O31: 36334000 | P31: 34079000 | Q31: 35149000 | R31: 33939000 | S31: 33011000 | T31: 31406000 | U31: 29875000 | V31: 29938000 | W31: 29861000 | X31: 28760000 | Y31: 27416000 | Z31: 26891000 | AA31: 20928000 | AB31: 20823000 | AC31: 20778000 | AD31: 20795000 | AE31: 21464000 | AF31: 21830000 | AG31: 22751000 | AH31: 34661000 | AI31: 36197000 | AJ31: 34961000 | AK31: 36428000 | AL31: 35707000 | AM31: 34519000 | AN31: 35378000 | AO31: 35596000 | AP31: 38826000 | AQ31: 37369000 | AR31: 43772000 | AS31: 46055000 | AT31: 50737000 | AU31: 47846000 | AV31: 43943000 | AW31: 46908000 | AX31: 48969000 | AY31: 55493000 | AZ31: 58311000 | BA31: 60693000 | BB31: 59581000 | BC31: 62868000 | BD31: 66812000 | BE31: 77491000 | BF31: 78928000 | BG31: 82804000 | BH31: 85967000 | BI31: 91030000 | BJ31: 97389000 | BK31: 113269000 | BL31: 148955000 | BM31: 63536000 | BN31: 60892000 | BO31: 41422000 | BP31: 50098000 | BQ31: 42326000 | BR31: 37090000 | BS31: 30850000 | BT31: 20006000 | BU31: 29346000 | BV31: 29264000 | BW31: 29156000 | BX31: 29317000 | BY31: 26464000 | BZ31: 11270000 | CA31: 11007000 | CB31: 11610000 | CC31: 12465000 | CD31: 15423000 | CE31: 20506000 | CF31: 21851000 | CG31: 8989000 | CH31: 7423000 | CI31: 124535000 | CJ31: 186421000 | CK31: 184319000 | CL31: 131733000 | CM31: 15959000 | CN31: 12936000 | CO31: 9025000 | CP31: 8933000 | CT31: 6459000 | CX31: 6684000 | DB31: 5012000 | DF31: 5166000 | DJ31: 5463000
A32: TotalLiabilitiesNetMinorityInterest | B32: 24097852000 | C32: 23868682000 | D32: 23541595000 | E32: 22913352000 | F32: 22050765000 | G32: 20994684000 | H32: 20065385000 | I32: 19735501000 | J32: 19350673000 | K32: 18986773000 | L32: 19201386000 | M32: 19167923000 | N32: 18491362000 | O32: 17638859000 | P32: 16122584000 | Q32: 15764495000 | R32: 15168369000 | S32: 14731615000 | T32: 6786645000 | U32: 6765133000 | V32: 6565007000 | W32: 6256912000 | X32: 6391137000 | Y32: 6630601000 | Z32: 6433729000 | AA32: 6267474000 | AB32: 6266004000 | AC32: 6555224000 | AD32: 6204009000 | AE32: 5928001000 | AF32: 5880009000 | AG32: 5944700000 | AH32: 5776261000 | AI32: 5570692000 | AJ32: 5514066000 | AK32: 5533735000 | AL32: 5729801000 | AM32: 5769657000 | AN32: 5465331000 | AO32: 5501020000 | AP32: 5468154000 | AQ32: 5314798000 | AR32: 5382352000 | AS32: 5538815000 | AT32: 5293064000 | AU32: 5178776000 | AV32: 5020025000 | AW32: 5181870000 | AX32: 5155539000 | AY32: 5495208000 | AZ32: 5491743000 | BA32: 5532184000 | BB32: 5496630000 | BC32: 5440550000 | BD32: 5473221000 | BE32: 6277118000 | BF32: 6123406000 | BG32: 6062216000 | BH32: 6057504000 | BI32: 6176637000 | BJ32: 6142987000 | BK32: 5932392000 | BL32: 5952558000 | BM32: 1277532000 | BN32: 1294767000 | BO32: 1503362000 | BP32: 1523720000 | BQ32: 1376653000 | BR32: 1271392000 | BS32: 1316494000 | BT32: 1192549000 | BU32: 1176572000 | BV32: 1156539000 | BW32: 1250527000 | BX32: 1116129000 | BY32: 1185686000 | BZ32: 1075789000 | CA32: 1087534000 | CB32: 963236000 | CC32: 1018220000 | CD32: 1045085000 | CE32: 1220813000 | CF32: 1133875000 | CG32: 1500072000 | CH32: 1510667000 | CI32: 1516106000 | CJ32: 1414294000 | CK32: 1405974000 | CL32: 1420699000 | CM32: 762620000 | CN32: 680603000 | CO32: 610764000 | CP32: 525020000 | CQ32: 687000000 | CR32: 504900000 | CS32: 537900000 | CT32: 486023000 | CU32: 647000000 | CV32: 507400000 | CW32: 419800000 | CX32: 330942000 | CY32: 502700000 | CZ32: 305100000 | DA32: 276600000 | DB32: 232618000 | DC32: 410600000 | DD32: 270300000 | DE32: 297200000 | DF32: 259985000 | DG32: 385900000 | DH32: 283100000 | DI32: 287400000 | DJ32: 217112000 | DK32: 268500000 | DL32: 211500000 | DM32: 183300000 | DN32: 156500000 | DO32: 235000000 | DP32: 169700000 | DQ32: 179400000 | DR32: 126600000 | DS32: 188600000 | DT32: 137600000 | DU32: 139100000 | DV32: 86300000 | DW32: 158900000 | DX32: 125600000 | DY32: 112200000 | DZ32: 76000000 | EA32: 146300000 | EB32: 123700000 | EC32: 128700000 | ED32: 73200000 | EE32: 135600000 | EF32: 117600000 | EG32: 98700000 | EH32: 115400000 | EI32: 123600000 | EJ32: 119600000
A33: CurrentLiabilities | B33: 6033922000 | C33: 6100679000 | D33: 5887768000 | E33: 6502647000 | F33: 7566786000 | G33: 6951841000 | H33: 5979357000 | I33: 5740499000 | J33: 5479084000 | K33: 5315398000 | L33: 5710783000 | M33: 5886211000 | N33: 5411188000 | O33: 4843228000 | P33: 4543560000 | Q33: 4506038000 | R33: 4312270000 | S33: 3956716000 | T33: 3015857000 | U33: 2982182000 | V33: 2915544000 | W33: 2525332000 | X33: 2964878000 | Y33: 2937806000 | Z33: 2806755000 | AA33: 2692041000 | AB33: 2622805000 | AC33: 2959739000 | AD33: 2719406000 | AE33: 2011594000 | AF33: 1995596000 | AG33: 1991583000 | AH33: 2154763000 | AI33: 2072939000 | AJ33: 1987740000 | AK33: 2010846000 | AL33: 1969418000 | AM33: 1863318000 | AN33: 1811971000 | AO33: 1753049000 | AP33: 1740190000 | AQ33: 1600402000 | AR33: 1738547000 | AS33: 1633839000 | AT33: 1526683000 | AU33: 1411253000 | AV33: 1509902000 | AW33: 1572221000 | AX33: 1526951000 | AY33: 1387230000 | AZ33: 1365373000 | BA33: 1410315000 | BB33: 1319160000 | BC33: 1206040000 | BD33: 1206500000 | BE33: 1310933000 | BF33: 1165825000 | BG33: 1092662000 | BH33: 1075235000 | BI33: 1192657000 | BJ33: 1164717000 | BK33: 954740000 | BL33: 858241000 | BM33: 750273000 | BN33: 832871000 | BO33: 948503000 | BP33: 944652000 | BQ33: 979492000 | BR33: 933797000 | BS33: 909940000 | BT33: 869368000 | BU33: 847778000 | BV33: 825692000 | BW33: 848659000 | BX33: 780869000 | BY33: 853417000 | BZ33: 743802000 | CA33: 760077000 | CB33: 633883000 | CC33: 640608000 | CD33: 664501000 | CE33: 673275000 | CF33: 581138000 | CG33: 1110601000 | CH33: 1133551000 | CI33: 1168932000 | CJ33: 516859000 | CK33: 510448000 | CL33: 537935000 | CM33: 500896000 | CN33: 423561000 | CO33: 553079000 | CP33: 472297000 | CQ33: 673500000 | CR33: 485300000 | CS33: 512700000 | CT33: 455134000 | CU33: 634500000 | CV33: 485500000 | CW33: 397800000 | CX33: 307711000 | CY33: 495900000 | CZ33: 298200000 | DA33: 267000000 | DB33: 224465000 | DC33: 404300000 | DD33: 264600000 | DE33: 291400000 | DF33: 253714000 | DG33: 379200000 | DH33: 276100000 | DI33: 280200000 | DJ33: 208963000 | DK33: 261400000 | DL33: 204200000 | DM33: 175900000 | DN33: 148200000 | DO33: 226600000 | DP33: 161200000 | DQ33: 170700000 | DR33: 117000000 | DS33: 178700000 | DT33: 97500000 | DU33: 112900000 | DV33: 62400000 | DW33: 111500000 | DX33: 85600000 | DY33: 86300000 | DZ33: 55100000 | EA33: 84700000 | EB33: 64800000 | EC33: 80700000 | ED33: 45100000 | EE33: 73600000 | EF33: 54500000 | EG33: 52400000 | EH33: 61400000 | EI33: 65200000 | EJ33: 50200000
A34: PayablesAndAccruedExpenses | B34: 4702489000 | C34: 4538926000 | D34: 4598829000 | E34: 5245587000 | F34: 5435087000 | G34: 4846163000 | H34: 4795798000 | I34: 4583254000 | J34: 4351243000 | K34: 4214029000 | L34: 4636704000 | M34: 4841843000 | N34: 4395455000 | O34: 3851594000 | P34: 3578200000 | Q34: 3564979000 | R34: 3396640000 | S34: 3061692000 | T34: 3013907000 | U34: 2980253000 | V34: 2913635000 | W34: 2523443000 | X34: 2563533000 | Y34: 2536274000 | Z34: 2405353000 | AA34: 2290853000 | AB34: 2121855000 | AC34: 2458259000 | AD34: 2217858000 | AE34: 2010068000 | AF34: 1994217000 | AG34: 1974097000 | AH34: 2021122000 | AI34: 1937822000 | AJ34: 1861314000 | AK34: 1870947000 | AL34: 1846971000 | AM34: 1738784000 | AN34: 1714210000 | AO34: 1666914000 | AP34: 1685690000 | AQ34: 1567973000 | AR34: 1637451000 | AS34: 1593163000 | AT34: 1510793000 | AU34: 1396628000 | AV34: 1428601000 | AW34: 1548632000 | AX34: 1490382000 | AY34: 1346349000 | AZ34: 1327362000 | BA34: 1364356000 | BB34: 1278278000 | BC34: 1156211000 | BD34: 1177768000 | BE34: 1237993000 | BF34: 1123996000 | BG34: 1061194000 | BH34: 1061077000 | BI34: 1161533000 | BJ34: 1161718000 | BK34: 951910000 | BL34: 854995000 | BM34: 743087000 | BN34: 824791000 | BO34: 940030000 | BP34: 935485000 | BQ34: 970692000 | BR34: 925012000 | BS34: 901076000 | BT34: 859807000 | BU34: 837041000 | BV34: 812832000 | BW34: 833955000 | BX34: 764913000 | BY34: 836537000 | BZ34: 727132000 | CA34: 742782000 | CB34: 616926000 | CC34: 624048000 | CD34: 648292000 | CE34: 657441000 | CF34: 566006000 | CG34: 714724000 | CH34: 737876000 | CI34: 777843000 | CJ34: 508917000 | CK34: 503365000 | CL34: 528900000 | CM34: 435905000 | CN34: 399235000 | CO34: 370125000 | CP34: 471064000 | CQ34: 347600000 | CR34: 209900000 | CS34: 246700000 | CT34: 454409000 | CU34: 280800000 | CV34: 214500000 | CW34: 179100000 | CX34: 284328000 | CY34: 210800000 | CZ34: 163100000 | DA34: 152700000 | DB34: 183966000 | DC34: 144700000 | DD34: 121200000 | DE34: 120400000 | DF34: 180032000 | DG34: 111900000 | DH34: 93600000 | DI34: 122700000 | DJ34: 177922000 | DK34: 88800000 | DL34: 91500000 | DM34: 101100000 | DN34: 81000000 | DO34: 112000000 | DP34: 83300000 | DQ34: 101300000 | DR34: 64000000 | DS34: 85400000 | DT34: 65700000 | DU34: 86300000 | DV34: 37800000 | DW34: 79300000 | DX34: 63500000 | DY34: 67300000 | DZ34: 31500000 | EA34: 56500000 | EB34: 40500000 | EC34: 57900000 | ED34: 22100000 | EE34: 51300000 | EF34: 37000000
A35: Payables | B35: 3688895000 | C35: 3690169000 | D35: 3561910000 | E35: 4135082000 | F35: 4365161000 | G35: 3915903000 | H35: 3746659000 | I35: 3544032000 | J35: 3378218000 | K35: 3352376000 | L35: 3630152000 | M35: 3781241000 | N35: 3416888000 | O35: 3060226000 | P35: 2869044000 | Q35: 2847512000 | R35: 2730389000 | S35: 2501685000 | T35: 2395502000 | U35: 2341609000 | V35: 2302246000 | W35: 2028072000 | X35: 2013875000 | Y35: 1982678000 | Z35: 1884326000 | AA35: 1831748000 | AB35: 1620989000 | AC35: 1953832000 | AD35: 1743432000 | AE35: 1569371000 | AF35: 1527095000 | AG35: 1500569000 | AH35: 1577958000 | AI35: 1544315000 | AJ35: 1447554000 | AK35: 1428088000 | AL35: 1419702000 | AM35: 1343957000 | AN35: 1345632000 | AO35: 1252033000 | AP35: 1272836000 | AQ35: 1208935000 | AR35: 1446323000 | AS35: 1200724000 | AT35: 1144522000 | AU35: 1036279000 | AV35: 1216468000 | AW35: 1133655000 | AX35: 1123759000 | AY35: 965927000 | AZ35: 979621000 | BA35: 985606000 | BB35: 956606000 | BC35: 823960000 | BD35: 835478000 | BE35: 856647000 | BF35: 819612000 | BG35: 728472000 | BH35: 686032000 | BI35: 721950000 | BJ35: 819990000 | BK35: 594995000 | BL35: 554039000 | BM35: 484997000 | BN35: 571233000 | BO35: 533269000 | BP35: 547616000 | BQ35: 591474000 | BR35: 552092000 | BS35: 528539000 | BT35: 512201000 | BU35: 514299000 | BV35: 478943000 | BW35: 497547000 | BX35: 459951000 | BY35: 548509000 | BZ35: 429516000 | CA35: 455058000 | CB35: 361899000 | CC35: 393760000 | CD35: 408394000 | CE35: 410626000 | CF35: 346786000 | CG35: 502134000 | CH35: 495096000 | CI35: 554335000 | CJ35: 294784000 | CK35: 302682000 | CL35: 314708000 | CM35: 313454000 | CN35: 277815000 | CO35: 255471000 | CP35: 349689000 | CQ35: 347600000 | CR35: 209900000 | CS35: 246700000 | CT35: 281584000 | CU35: 280800000 | CV35: 214500000 | CW35: 179100000 | CX35: 192301000 | CY35: 210800000 | CZ35: 163100000 | DA35: 152700000 | DB35: 113525000 | DC35: 144700000 | DD35: 121200000 | DE35: 120400000 | DF35: 117933000 | DG35: 111900000 | DH35: 93600000 | DI35: 122700000 | DJ35: 116885000 | DK35: 88800000 | DL35: 91500000 | DM35: 101100000 | DN35: 81000000 | DO35: 112000000 | DP35: 83300000 | DQ35: 101300000 | DR35: 64000000 | DS35: 85400000 | DT35: 65700000 | DU35: 86300000 | DV35: 37800000 | DW35: 79300000 | DX35: 63500000 | DY35: 67300000 | DZ35: 31500000 | EA35: 56500000 | EB35: 40500000 | EC35: 57900000 | ED35: 22100000 | EE35: 51300000 | EF35: 37000000
A36: AccountsPayable | B36: 3681634000 | C36: 3679170000 | D36: 3552991000 | E36: 4127076000 | F36: 4358388000 | G36: 3906852000 | H36: 3738604000 | I36: 3532639000 | J36: 3369984000 | K36: 3294423000 | L36: 3614089000 | M36: 3770528000 | N36: 3400642000 | O36: 2954361000 | P36: 2860682000 | Q36: 2844171000 | R36: 2727079000 | S36: 2452898000 | T36: 2385469000 | U36: 2336772000 | V36: 2294996000 | W36: 2018320000 | X36: 2009771000 | Y36: 1978032000 | Z36: 1880668000 | AA36: 1622776000 | AB36: 1557596000 | AC36: 1948111000 | AD36: 1720772000 | AE36: 1447223000 | AF36: 1494225000 | AG36: 1470107000 | AH36: 1536610000 | AI36: 1435367000 | AJ36: 1388154000 | AK36: 1394873000 | AL36: 1395780000 | AM36: 1222680000 | AN36: 1286484000 | AO36: 1251394000 | AP36: 1254856000 | AQ36: 1138395000 | AR36: 1261607000 | AS36: 1199727000 | AT36: 1143857000 | AU36: 985924000 | AV36: 1064087000 | AW36: 1132544000 | AX36: 1122949000 | AY36: 933710000 | AZ36: 953641000 | BA36: 971538000 | BB36: 941742000 | BC36: 789274000 | BD36: 830953000 | BE36: 852988000 | BF36: 800308000 | BG36: 700438000 | BH36: 678421000 | BI36: 720126000 | BJ36: 818246000 | BK36: 592071000 | BL36: 551040000 | BM36: 484949000 | BN36: 555274000 | BO36: 517443000 | BP36: 538046000 | BQ36: 569447000 | BR36: 508386000 | BS36: 521087000 | BT36: 462697000 | BU36: 459742000 | BV36: 409327000 | BW36: 475841000 | BX36: 440485000 | BY36: 510187000 | BZ36: 383791000 | CA36: 440505000 | CB36: 352717000 | CC36: 357224000 | CD36: 341303000 | CE36: 410426000 | CF36: 346786000 | CG36: 341134000 | CH36: 322463000 | CI36: 381843000 | CJ36: 294784000 | CK36: 282560000 | CL36: 297262000 | CM36: 309508000 | CN36: 277815000 | CO36: 242361000 | CP36: 334554000 | CQ36: 347600000 | CR36: 209900000 | CS36: 246700000 | CT36: 257759000 | CU36: 280800000 | CV36: 214500000 | CW36: 179100000 | CX36: 179958000 | CY36: 210800000 | CZ36: 163100000 | DA36: 152700000 | DB36: 103523000 | DC36: 144700000 | DD36: 121200000 | DE36: 120400000 | DF36: 103176000 | DG36: 111900000 | DH36: 93600000 | DI36: 122700000 | DJ36: 111675000 | DK36: 88800000 | DL36: 91500000 | DM36: 101100000 | DN36: 81000000 | DO36: 112000000 | DP36: 83300000 | DQ36: 101300000 | DR36: 64000000 | DS36: 85400000 | DT36: 65700000 | DU36: 86300000 | DV36: 37800000 | DW36: 79300000 | DX36: 63500000 | DY36: 67300000 | DZ36: 31500000 | EA36: 56500000 | EB36: 40500000 | EC36: 57900000 | ED36: 22100000 | EE36: 51300000 | EF36: 37000000
A37: TotalTaxPayable | B37: 7261000 | C37: 10999000 | D37: 8919000 | E37: 8006000 | F37: 6773000 | G37: 9051000 | H37: 8055000 | I37: 11393000 | J37: 8234000 | K37: 57953000 | L37: 16063000 | M37: 10713000 | N37: 16246000 | O37: 105865000 | P37: 8362000 | Q37: 3341000 | R37: 3310000 | S37: 48787000 | T37: 10033000 | U37: 4837000 | V37: 7250000 | W37: 9752000 | X37: 4104000 | Y37: 4646000 | Z37: 3658000 | AA37: 208972000 | AB37: 63393000 | AC37: 5721000 | AD37: 22660000 | AE37: 122148000 | AF37: 32870000 | AG37: 30462000 | AH37: 41348000 | AI37: 108948000 | AJ37: 59400000 | AK37: 33215000 | AL37: 23922000 | AM37: 121277000 | AN37: 59148000 | AO37: 639000 | AP37: 17980000 | AQ37: 70540000 | AR37: 184716000 | AS37: 997000 | AT37: 665000 | AU37: 50355000 | AV37: 152381000 | AW37: 1111000 | AX37: 810000 | AY37: 32217000 | AZ37: 25980000 | BA37: 14068000 | BB37: 14864000 | BC37: 34686000 | BD37: 4525000 | BE37: 3659000 | BF37: 19304000 | BG37: 28034000 | BH37: 7611000 | BI37: 1824000 | BJ37: 1744000 | BK37: 2924000 | BL37: 2999000 | BM37: 48000 | BN37: 15959000 | BO37: 15826000 | BP37: 9570000 | BQ37: 22027000 | BR37: 43706000 | BS37: 7452000 | BT37: 49504000 | BU37: 54557000 | BV37: 69616000 | BW37: 21706000 | BX37: 19466000 | BY37: 38322000 | BZ37: 45725000 | CA37: 14553000 | CB37: 9182000 | CC37: 36536000 | CD37: 67091000 | CH37: 10633000 | CI37: 10492000 | CJ37: 0 | CK37: 20122000 | CL37: 17446000 | CM37: 3946000 | CN37: 0 | CO37: 13110000 | CP37: 15135000 | CT37: 23825000 | CX37: 12343000 | DB37: 10002000 | DF37: 14757000 | DJ37: 5210000
A38: IncomeTaxPayable | B38: 7261000 | C38: 10999000 | D38: 8919000 | E38: 8006000 | F38: 6773000 | G38: 9051000 | H38: 8055000 | I38: 11393000 | J38: 8234000 | K38: 57953000 | L38: 16063000 | M38: 10713000 | N38: 16246000 | O38: 105865000 | P38: 8362000 | Q38: 3341000 | R38: 3310000 | S38: 48787000 | T38: 10033000 | U38: 4837000 | V38: 7250000 | W38: 9752000 | X38: 4104000 | Y38: 4646000 | Z38: 3658000 | AA38: 208972000 | AB38: 63393000 | AC38: 5721000 | AD38: 22660000 | AE38: 122148000 | AF38: 32870000 | AG38: 30462000 | AH38: 41348000 | AI38: 108948000 | AJ38: 59400000 | AK38: 33215000 | AL38: 23922000 | AM38: 121277000 | AN38: 59148000 | AO38: 639000 | AP38: 17980000 | AQ38: 70540000 | AR38: 95387000 | AS38: 997000 | AT38: 665000 | AU38: 50355000 | AV38: 44428000 | AW38: 1111000 | AX38: 810000 | AY38: 32217000 | AZ38: 25980000 | BA38: 14068000 | BB38: 14864000 | BC38: 34686000 | BD38: 4525000 | BE38: 3659000 | BF38: 19304000 | BG38: 28034000 | BH38: 7611000 | BI38: 1824000 | BJ38: 1744000 | BK38: 2924000 | BL38: 2999000 | BM38: 48000 | BN38: 15959000 | BO38: 15826000 | BP38: 9570000 | BQ38: 22027000 | BR38: 43706000 | BS38: 7452000 | BT38: 49504000 | BU38: 54557000 | BV38: 69616000 | BW38: 21706000 | BX38: 19466000 | BY38: 38322000 | BZ38: 45725000 | CA38: 14553000 | CB38: 9182000 | CC38: 36536000 | CD38: 67091000 | CH38: 10633000 | CI38: 10492000 | CJ38: 0 | CK38: 20122000 | CL38: 17446000 | CM38: 3946000 | CN38: 0 | CO38: 13110000 | CP38: 15135000 | CT38: 23825000 | CX38: 12343000 | DB38: 10002000 | DF38: 14757000 | DJ38: 5210000
A39: OtherPayable | CE39: 200000 | CG39: 161000000 | CH39: 162000000 | CI39: 162000000
A40: CurrentAccruedExpenses | B40: 1013594000 | C40: 848757000 | D40: 1036919000 | E40: 1110505000 | F40: 1069926000 | G40: 930260000 | H40: 1049139000 | I40: 1039222000 | J40: 973025000 | K40: 861653000 | L40: 1006552000 | M40: 1060602000 | N40: 978567000 | O40: 791368000 | P40: 709156000 | Q40: 717467000 | R40: 666251000 | S40: 560007000 | T40: 618405000 | U40: 638644000 | V40: 611389000 | W40: 495371000 | X40: 549658000 | Y40: 553596000 | Z40: 521027000 | AA40: 459105000 | AB40: 500866000 | AC40: 504427000 | AD40: 474426000 | AE40: 440697000 | AF40: 467122000 | AG40: 473528000 | AH40: 443164000 | AI40: 393507000 | AJ40: 413760000 | AK40: 442859000 | AL40: 427269000 | AM40: 394827000 | AN40: 368578000 | AO40: 414881000 | AP40: 412854000 | AQ40: 359038000 | AR40: 191128000 | AS40: 392439000 | AT40: 366271000 | AU40: 360349000 | AV40: 212133000 | AW40: 414977000 | AX40: 366623000 | AY40: 380422000 | AZ40: 347741000 | BA40: 378750000 | BB40: 321672000 | BC40: 332251000 | BD40: 342290000 | BE40: 381346000 | BF40: 304384000 | BG40: 332722000 | BH40: 375045000 | BI40: 439583000 | BJ40: 341728000 | BK40: 356915000 | BL40: 300956000 | BM40: 258090000 | BN40: 253558000 | BO40: 406761000 | BP40: 387869000 | BQ40: 379218000 | BR40: 372920000 | BS40: 372537000 | BT40: 347606000 | BU40: 322742000 | BV40: 333889000 | BW40: 336408000 | BX40: 304962000 | BY40: 288028000 | BZ40: 297616000 | CA40: 287724000 | CB40: 255027000 | CC40: 230288000 | CD40: 239898000 | CE40: 246815000 | CF40: 219220000 | CG40: 212590000 | CH40: 242780000 | CI40: 223508000 | CJ40: 214133000 | CK40: 200683000 | CL40: 214192000 | CM40: 122451000 | CN40: 121420000 | CO40: 114654000 | CP40: 121375000 | CT40: 172825000 | CX40: 92027000 | DB40: 70441000 | DF40: 62099000 | DJ40: 61037000
...

Sheet DG_quarterly_pl
A1: name | B1: ttm | C1: 45138 | D1: 45046 | E1: 44957 | F1: 44865 | G1: 44773 | H1: 44681 | I1: 44592 | J1: 44500 | K1: 44408 | L1: 44316 | M1: 44227 | N1: 44135 | O1: 44043 | P1: 43951 | Q1: 43861 | R1: 43769 | S1: 43677 | T1: 43585 | U1: 43496 | V1: 43404 | W1: 43312 | X1: 43220 | Y1: 43131 | Z1: 43039 | AA1: 42947 | AB1: 42855 | AC1: 42766 | AD1: 42674 | AE1: 42582 | AF1: 42490 | AG1: 42400 | AH1: 42308 | AI1: 42216 | AJ1: 42124 | AK1: 42035 | AL1: 41943 | AM1: 41851 | AN1: 41759 | AO1: 41670 | AP1: 41578 | AQ1: 41486 | AR1: 41394 | AS1: 41305 | AT1: 41213 | AU1: 41121 | AV1: 41029 | AW1: 40939 | AX1: 40847 | AY1: 40755 | AZ1: 40663 | BA1: 40574 | BB1: 40482 | BC1: 40390 | BD1: 40298 | BE1: 40209 | BF1: 40117 | BG1: 40025 | BH1: 39933 | BI1: 39844 | BJ1: 39752 | BK1: 39660 | BL1: 39568 | BM1: 39478 | BN1: 39386 | BO1: 39294 | BP1: 39202 | BQ1: 39113 | BR1: 39021 | BS1: 38929 | BT1: 38837 | BU1: 38748 | BV1: 38656 | BW1: 38564 | BX1: 38472 | BY1: 38383 | BZ1: 38291 | CA1: 38199 | CB1: 38107 | CC1: 38017 | CD1: 37925 | CE1: 37833 | CF1: 37741 | CG1: 37652 | CH1: 37560 | CI1: 37468 | CJ1: 37376 | CK1: 37287 | CL1: 37195 | CM1: 37103 | CN1: 37011 | CO1: 36922 | CP1: 36830 | CQ1: 36738 | CR1: 36646 | CS1: 36556 | CT1: 36464 | CU1: 36372 | CV1: 36280 | CW1: 36191 | CX1: 36099 | CY1: 36007 | CZ1: 35915 | DA1: 35826 | DB1: 35734 | DC1: 35642 | DD1: 35550 | DE1: 35461 | DF1: 35369 | DG1: 35277 | DH1: 35185 | DI1: 35095 | DJ1: 35003 | DK1: 34911 | DL1: 34819 | DM1: 34730 | DN1: 34638 | DO1: 34546 | DP1: 34454 | DQ1: 34365 | DR1: 34273 | DS1: 34181 | DT1: 34089 | DU1: 34000 | DV1: 33908 | DW1: 33816 | DX1: 33724 | DY1: 33634 | DZ1: 33542 | EA1: 33450 | EB1: 33358 | EC1: 33269 | ED1: 33177 | EE1: 33085 | EF1: 32993 | EG1: 32904 | EH1: 32812 | EI1: 32720 | EJ1: 32628 | EK1: 32539 | EL1: 32447 | EM1: 32355 | EN1: 32263 | EO1: 32142 | EP1: 32050 | EQ1: 31958 | ER1: 31867 | ES1: 31777 | ET1: 31685 | EU1: 31593 | EV1: 31502 | EW1: 31412 | EX1: 31320
A2: TotalRevenue | B2: 38806811000 | C2: 9796181000 | D2: 9342832000 | E2: 10202907000 | F2: 9464891000 | G2: 9425713000 | H2: 8751352000 | I2: 8651448000 | J2: 8517839000 | K2: 8650198000 | L2: 8400964000 | M2: 8414524000 | N2: 8199625000 | O2: 8684241000 | P2: 8448449000 | Q2: 7157642000 | R2: 6991393000 | S2: 6981753000 | T2: 6623185000 | U2: 6649809000 | V2: 6417462000 | W2: 6443309000 | X2: 6114463000 | Y2: 6129431000 | Z2: 5903606000 | AA2: 5828305000 | AB2: 5609625000 | AC2: 6009246000 | AD2: 5320029000 | AE2: 5391891000 | AF2: 5265432000 | AG2: 5286938000 | AH2: 5067048000 | AI2: 5095904000 | AJ2: 4918672000 | AK2: 4939059000 | AL2: 4724409000 | AM2: 4724039000 | AN2: 4522081000 | AO2: 4493945000 | AP2: 4381838000 | AQ2: 4394651000 | AR2: 4233733000 | AS2: 4207621000 | AT2: 3964647000 | AU2: 3948655000 | AV2: 3901205000 | AW2: 4185073000 | AX2: 3595224000 | AY2: 3575194000 | AZ2: 3451697000 | BA2: 3486104000 | BB2: 3223427000 | BC2: 3214155000 | BD2: 3111314000 | BE2: 3185785000 | BF2: 2928751000 | BG2: 2901907000 | BH2: 2779937000 | BI2: 2845848000 | BJ2: 2598938000 | BK2: 2609384000 | BL2: 2403498000 | BM2: 2559573000 | BN2: 2312842000 | BO2: 2347564000 | BP2: 2275267000 | BQ2: 2553986000 | BR2: 2213396000 | BS2: 2251053000 | BT2: 2151387000 | BU2: 2480504000 | BV2: 2057888000 | BW2: 2066016000 | BX2: 1977829000 | BY2: 2197538000 | BZ2: 1879187000 | CA2: 1836243000 | CB2: 1747959000 | CC2: 1966488000 | CD2: 1685346000 | CE2: 1651094000 | CF2: 1569064000 | CG2: 1759563000 | CH2: 1497702000 | CI2: 1453727000 | CJ2: 1389412000 | CK2: 1586012000 | CL2: 1309125000 | CM2: 1225254000 | CN2: 1202504000 | CO2: 1441714000 | CP2: 1094360000 | CQ2: 1017418000 | CR2: 997079000 | CS2: 1177764000 | CT2: 950400000 | CU2: 915200000 | CV2: 844600000 | CW2: 992989000 | CX2: 781400000 | CY2: 741400000 | CZ2: 705300000 | DA2: 861125000 | DB2: 649400000 | DC2: 596800000 | DD2: 520000000 | DE2: 675198000 | DF2: 509000000 | DG2: 494400000 | DH2: 455900000 | DI2: 575388000 | DJ2: 437200000 | DK2: 408200000 | DL2: 343400000 | DM2: 484809000 | DN2: 359400000 | DO2: 317300000 | DP2: 287100000 | DQ2: 383100000 | DR2: 272600000 | DS2: 255600000 | DT2: 221800000 | DU2: 291700000 | DV2: 223500000 | DW2: 216900000 | DX2: 188600000 | DY2: 243000000 | DZ2: 189700000 | EA2: 173300000 | EB2: 148300000 | EC2: 201900000 | ED2: 164600000 | EE2: 153000000 | EF2: 133800000 | EG2: 192000000 | EH2: 145600000 | EI2: 147600000 | EJ2: 129900000 | EK2: 190100000 | EL2: 153100000 | EM2: 145600000 | EN2: 124200000 | EO2: 189500000 | EP2: 136900000 | EQ2: 146000000 | ER2: 116000000 | ES2: 186200000 | ET2: 134000000 | EU2: 135900000 | EV2: 108700000 | EW2: 182000000 | EX2: 138700000
